[14/Sep/2018 14:38:49] "GET /snower/ HTTP/1.1" 200 25
[14/Sep/2018 14:38:50] "GET /snower/ HTTP/1.1" 200 25
[14/Sep/2018 14:40:02] "GET /snower/ HTTP/1.1" 200 25
Internal Server Error: /snower/
Traceback (most recent call last):
  File "/usr/local/lib/python2.7/site-packages/django/core/handlers/exception.py", line 41, in inner
    response = get_response(request)
  File "/usr/local/lib/python2.7/site-packages/django/core/handlers/base.py", line 187, in _get_response
    response = self.process_exception_by_middleware(e, request)
  File "/usr/local/lib/python2.7/site-packages/django/core/handlers/base.py", line 185, in _get_response
    response = wrapped_callback(request, *callback_args, **callback_kwargs)
  File "/Users/pengbaojiang/pengbaojiang/code/python_src/python_learning/snower/pollsite/pollsite/snower/views.py", line 11, in snower
    return render(request, 'snower/snower.html')
  File "/usr/local/lib/python2.7/site-packages/django/shortcuts.py", line 30, in render
    content = loader.render_to_string(template_name, context, request, using=using)
  File "/usr/local/lib/python2.7/site-packages/django/template/loader.py", line 68, in render_to_string
    return template.render(context, request)
  File "/usr/local/lib/python2.7/site-packages/django/template/backends/django.py", line 66, in render
    return self.template.render(context)
  File "/usr/local/lib/python2.7/site-packages/django/template/base.py", line 207, in render
    return self._render(context)
  File "/usr/local/lib/python2.7/site-packages/django/template/base.py", line 199, in _render
    return self.nodelist.render(context)
  File "/usr/local/lib/python2.7/site-packages/django/template/base.py", line 990, in render
    bit = node.render_annotated(context)
  File "/usr/local/lib/python2.7/site-packages/django/template/base.py", line 957, in render_annotated
    return self.render(context)
  File "/usr/local/lib/python2.7/site-packages/django/template/defaulttags.py", line 458, in render
    url = reverse(view_name, args=args, kwargs=kwargs, current_app=current_app)
  File "/usr/local/lib/python2.7/site-packages/django/urls/base.py", line 91, in reverse
    return force_text(iri_to_uri(resolver._reverse_with_prefix(view, prefix, *args, **kwargs)))
  File "/usr/local/lib/python2.7/site-packages/django/urls/resolvers.py", line 497, in _reverse_with_prefix
    raise NoReverseMatch(msg)
NoReverseMatch: Reverse for 'imagekitchen' with no arguments not found. 1 pattern(s) tried: ['snower/r^imagekitchen/']
[14/Sep/2018 14:40:25] "GET /snower/ HTTP/1.1" 500 111233
Performing system checks...

System check identified no issues (0 silenced).
September 14, 2018 - 14:38:32
Django version 1.11.15, using settings 'pollsite.settings'
Starting development server at http://127.0.0.1:8000/
Quit the server with CONTROL-C.
Internal Server Error: /snower/
Traceback (most recent call last):
  File "/usr/local/lib/python2.7/site-packages/django/core/handlers/exception.py", line 41, in inner
    response = get_response(request)
  File "/usr/local/lib/python2.7/site-packages/django/core/handlers/base.py", line 187, in _get_response
    response = self.process_exception_by_middleware(e, request)
  File "/usr/local/lib/python2.7/site-packages/django/core/handlers/base.py", line 185, in _get_response
    response = wrapped_callback(request, *callback_args, **callback_kwargs)
  File "/Users/pengbaojiang/pengbaojiang/code/python_src/python_learning/snower/pollsite/pollsite/snower/views.py", line 11, in snower
    return render(request, 'snower/snower.html')
  File "/usr/local/lib/python2.7/site-packages/django/shortcuts.py", line 30, in render
    content = loader.render_to_string(template_name, context, request, using=using)
  File "/usr/local/lib/python2.7/site-packages/django/template/loader.py", line 68, in render_to_string
    return template.render(context, request)
  File "/usr/local/lib/python2.7/site-packages/django/template/backends/django.py", line 66, in render
    return self.template.render(context)
  File "/usr/local/lib/python2.7/site-packages/django/template/base.py", line 207, in render
    return self._render(context)
  File "/usr/local/lib/python2.7/site-packages/django/template/base.py", line 199, in _render
    return self.nodelist.render(context)
  File "/usr/local/lib/python2.7/site-packages/django/template/base.py", line 990, in render
    bit = node.render_annotated(context)
  File "/usr/local/lib/python2.7/site-packages/django/template/base.py", line 957, in render_annotated
    return self.render(context)
  File "/usr/local/lib/python2.7/site-packages/django/template/defaulttags.py", line 458, in render
    url = reverse(view_name, args=args, kwargs=kwargs, current_app=current_app)
  File "/usr/local/lib/python2.7/site-packages/django/urls/base.py", line 91, in reverse
    return force_text(iri_to_uri(resolver._reverse_with_prefix(view, prefix, *args, **kwargs)))
  File "/usr/local/lib/python2.7/site-packages/django/urls/resolvers.py", line 497, in _reverse_with_prefix
    raise NoReverseMatch(msg)
NoReverseMatch: Reverse for 'imagekitchen' with no arguments not found. 1 pattern(s) tried: ['snower/r^/imagekitchen/']
[14/Sep/2018 14:40:41] "GET /snower/ HTTP/1.1" 500 111250
Performing system checks...

System check identified no issues (0 silenced).
September 14, 2018 - 14:40:40
Django version 1.11.15, using settings 'pollsite.settings'
Starting development server at http://127.0.0.1:8000/
Quit the server with CONTROL-C.
Unhandled exception in thread started by <function wrapper at 0x1108bc500>
Performing system checks...

Traceback (most recent call last):
  File "/usr/local/lib/python2.7/site-packages/django/utils/autoreload.py", line 228, in wrapper
    fn(*args, **kwargs)
  File "/usr/local/lib/python2.7/site-packages/django/core/management/commands/runserver.py", line 124, in inner_run
    self.check(display_num_errors=True)
  File "/usr/local/lib/python2.7/site-packages/django/core/management/base.py", line 359, in check
    include_deployment_checks=include_deployment_checks,
  File "/usr/local/lib/python2.7/site-packages/django/core/management/base.py", line 346, in _run_checks
    return checks.run_checks(**kwargs)
  File "/usr/local/lib/python2.7/site-packages/django/core/checks/registry.py", line 81, in run_checks
    new_errors = check(app_configs=app_configs)
  File "/usr/local/lib/python2.7/site-packages/django/core/checks/urls.py", line 16, in check_url_config
    return check_resolver(resolver)
  File "/usr/local/lib/python2.7/site-packages/django/core/checks/urls.py", line 26, in check_resolver
    return check_method()
  File "/usr/local/lib/python2.7/site-packages/django/urls/resolvers.py", line 256, in check
    for pattern in self.url_patterns:
  File "/usr/local/lib/python2.7/site-packages/django/utils/functional.py", line 35, in __get__
    res = instance.__dict__[self.name] = self.func(instance)
  File "/usr/local/lib/python2.7/site-packages/django/urls/resolvers.py", line 407, in url_patterns
    patterns = getattr(self.urlconf_module, "urlpatterns", self.urlconf_module)
  File "/usr/local/lib/python2.7/site-packages/django/utils/functional.py", line 35, in __get__
    res = instance.__dict__[self.name] = self.func(instance)
  File "/usr/local/lib/python2.7/site-packages/django/urls/resolvers.py", line 400, in urlconf_module
    return import_module(self.urlconf_name)
  File "/usr/local/Cellar/python@2/2.7.15_1/Frameworks/Python.framework/Versions/2.7/lib/python2.7/importlib/__init__.py", line 37, in import_module
    __import__(name)
  File "/Users/pengbaojiang/pengbaojiang/code/python_src/python_learning/snower/pollsite/pollsite/pollsite/urls.py", line 21, in <module>
    url(r'^snower/', include('snower.urls')),
  File "/usr/local/lib/python2.7/site-packages/django/conf/urls/__init__.py", line 50, in include
    urlconf_module = import_module(urlconf_module)
  File "/usr/local/Cellar/python@2/2.7.15_1/Frameworks/Python.framework/Versions/2.7/lib/python2.7/importlib/__init__.py", line 37, in import_module
    __import__(name)
  File "/Users/pengbaojiang/pengbaojiang/code/python_src/python_learning/snower/pollsite/pollsite/snower/urls.py", line 7
    url('r'^/imagekitchen/', views.imagekitchen, name="imagekitchen")
            ^
SyntaxError: invalid syntax
[14/Sep/2018 14:41:15] "GET /snower/ HTTP/1.1" 200 100
Internal Server Error: /snower//imagekitchen/
Traceback (most recent call last):
  File "/usr/local/lib/python2.7/site-packages/django/core/handlers/exception.py", line 41, in inner
    response = get_response(request)
  File "/usr/local/lib/python2.7/site-packages/django/core/handlers/base.py", line 198, in _get_response
    "returned None instead." % (callback.__module__, view_name)
ValueError: The view snower.views.imagekitchen didn't return an HttpResponse object. It returned None instead.
[14/Sep/2018 14:41:16] "GET /snower//imagekitchen/ HTTP/1.1" 500 54640
Performing system checks...

System check identified no issues (0 silenced).
September 14, 2018 - 14:41:12
Django version 1.11.15, using settings 'pollsite.settings'
Starting development server at http://127.0.0.1:8000/
Quit the server with CONTROL-C.
Not Found: /snower//imagekitchen/
[14/Sep/2018 14:41:25] "GET /snower//imagekitchen/ HTTP/1.1" 404 2463
Performing system checks...

System check identified no issues (0 silenced).
September 14, 2018 - 14:41:24
Django version 1.11.15, using settings 'pollsite.settings'
Starting development server at http://127.0.0.1:8000/
Quit the server with CONTROL-C.
Not Found: /snower//imagekitchen/
[14/Sep/2018 14:41:54] "GET /snower//imagekitchen/ HTTP/1.1" 404 2463
Internal Server Error: /snower/imagekitchen/
Traceback (most recent call last):
  File "/usr/local/lib/python2.7/site-packages/django/core/handlers/exception.py", line 41, in inner
    response = get_response(request)
  File "/usr/local/lib/python2.7/site-packages/django/core/handlers/base.py", line 198, in _get_response
    "returned None instead." % (callback.__module__, view_name)
ValueError: The view snower.views.imagekitchen didn't return an HttpResponse object. It returned None instead.
[14/Sep/2018 14:42:00] "GET /snower/imagekitchen/ HTTP/1.1" 500 54482
Performing system checks...

System check identified no issues (0 silenced).
September 14, 2018 - 14:41:53
Django version 1.11.15, using settings 'pollsite.settings'
Starting development server at http://127.0.0.1:8000/
Quit the server with CONTROL-C.
Performing system checks...

System check identified no issues (0 silenced).
September 14, 2018 - 14:43:35
Django version 1.11.15, using settings 'pollsite.settings'
Starting development server at http://127.0.0.1:8000/
Quit the server with CONTROL-C.
Internal Server Error: /snower/imagekitchen/
Traceback (most recent call last):
  File "/usr/local/lib/python2.7/site-packages/django/core/handlers/exception.py", line 41, in inner
    response = get_response(request)
  File "/usr/local/lib/python2.7/site-packages/django/core/handlers/base.py", line 198, in _get_response
    "returned None instead." % (callback.__module__, view_name)
ValueError: The view snower.views.imagekitchen didn't return an HttpResponse object. It returned None instead.
[14/Sep/2018 14:43:49] "GET /snower/imagekitchen/ HTTP/1.1" 500 54617
Performing system checks...

System check identified no issues (0 silenced).
September 14, 2018 - 14:43:44
Django version 1.11.15, using settings 'pollsite.settings'
Starting development server at http://127.0.0.1:8000/
Quit the server with CONTROL-C.
[14/Sep/2018 14:45:17] "GET /snower/imagekitchen/ HTTP/1.1" 200 13
[14/Sep/2018 14:45:22] "GET /snower/ HTTP/1.1" 200 99
[14/Sep/2018 14:45:23] "GET /snower/imagekitchen/ HTTP/1.1" 200 13
[14/Sep/2018 14:45:32] "GET /snower/imagekitchen/ HTTP/1.1" 200 13
[14/Sep/2018 14:46:55] "GET /snower/imagekitchen/ HTTP/1.1" 200 13
Performing system checks...

System check identified no issues (0 silenced).
September 14, 2018 - 14:45:08
Django version 1.11.15, using settings 'pollsite.settings'
Starting development server at http://127.0.0.1:8000/
Quit the server with CONTROL-C.
Performing system checks...

System check identified no issues (0 silenced).
September 14, 2018 - 14:47:09
Django version 1.11.15, using settings 'pollsite.settings'
Starting development server at http://127.0.0.1:8000/
Quit the server with CONTROL-C.
Unhandled exception in thread started by <function wrapper at 0x106e01500>
Performing system checks...

Traceback (most recent call last):
  File "/usr/local/lib/python2.7/site-packages/django/utils/autoreload.py", line 228, in wrapper
    fn(*args, **kwargs)
  File "/usr/local/lib/python2.7/site-packages/django/core/management/commands/runserver.py", line 124, in inner_run
    self.check(display_num_errors=True)
  File "/usr/local/lib/python2.7/site-packages/django/core/management/base.py", line 359, in check
    include_deployment_checks=include_deployment_checks,
  File "/usr/local/lib/python2.7/site-packages/django/core/management/base.py", line 346, in _run_checks
    return checks.run_checks(**kwargs)
  File "/usr/local/lib/python2.7/site-packages/django/core/checks/registry.py", line 81, in run_checks
    new_errors = check(app_configs=app_configs)
  File "/usr/local/lib/python2.7/site-packages/django/core/checks/urls.py", line 16, in check_url_config
    return check_resolver(resolver)
  File "/usr/local/lib/python2.7/site-packages/django/core/checks/urls.py", line 26, in check_resolver
    return check_method()
  File "/usr/local/lib/python2.7/site-packages/django/urls/resolvers.py", line 256, in check
    for pattern in self.url_patterns:
  File "/usr/local/lib/python2.7/site-packages/django/utils/functional.py", line 35, in __get__
    res = instance.__dict__[self.name] = self.func(instance)
  File "/usr/local/lib/python2.7/site-packages/django/urls/resolvers.py", line 407, in url_patterns
    patterns = getattr(self.urlconf_module, "urlpatterns", self.urlconf_module)
  File "/usr/local/lib/python2.7/site-packages/django/utils/functional.py", line 35, in __get__
    res = instance.__dict__[self.name] = self.func(instance)
  File "/usr/local/lib/python2.7/site-packages/django/urls/resolvers.py", line 400, in urlconf_module
    return import_module(self.urlconf_name)
  File "/usr/local/Cellar/python@2/2.7.15_1/Frameworks/Python.framework/Versions/2.7/lib/python2.7/importlib/__init__.py", line 37, in import_module
    __import__(name)
  File "/Users/pengbaojiang/pengbaojiang/code/python_src/python_learning/snower/pollsite/pollsite/pollsite/urls.py", line 21, in <module>
    url(r'^snower/', include('snower.urls')),
  File "/usr/local/lib/python2.7/site-packages/django/conf/urls/__init__.py", line 50, in include
    urlconf_module = import_module(urlconf_module)
  File "/usr/local/Cellar/python@2/2.7.15_1/Frameworks/Python.framework/Versions/2.7/lib/python2.7/importlib/__init__.py", line 37, in import_module
    __import__(name)
  File "/Users/pengbaojiang/pengbaojiang/code/python_src/python_learning/snower/pollsite/pollsite/snower/urls.py", line 8
    url(r'^imagekitchen/data/$', views.imagedata)
      ^
SyntaxError: invalid syntax
Unhandled exception in thread started by <function wrapper at 0x10c357500>
Performing system checks...

Traceback (most recent call last):
  File "/usr/local/lib/python2.7/site-packages/django/utils/autoreload.py", line 228, in wrapper
    fn(*args, **kwargs)
  File "/usr/local/lib/python2.7/site-packages/django/core/management/commands/runserver.py", line 124, in inner_run
    self.check(display_num_errors=True)
  File "/usr/local/lib/python2.7/site-packages/django/core/management/base.py", line 359, in check
    include_deployment_checks=include_deployment_checks,
  File "/usr/local/lib/python2.7/site-packages/django/core/management/base.py", line 346, in _run_checks
    return checks.run_checks(**kwargs)
  File "/usr/local/lib/python2.7/site-packages/django/core/checks/registry.py", line 81, in run_checks
    new_errors = check(app_configs=app_configs)
  File "/usr/local/lib/python2.7/site-packages/django/core/checks/urls.py", line 16, in check_url_config
    return check_resolver(resolver)
  File "/usr/local/lib/python2.7/site-packages/django/core/checks/urls.py", line 26, in check_resolver
    return check_method()
  File "/usr/local/lib/python2.7/site-packages/django/urls/resolvers.py", line 256, in check
    for pattern in self.url_patterns:
  File "/usr/local/lib/python2.7/site-packages/django/utils/functional.py", line 35, in __get__
    res = instance.__dict__[self.name] = self.func(instance)
  File "/usr/local/lib/python2.7/site-packages/django/urls/resolvers.py", line 407, in url_patterns
    patterns = getattr(self.urlconf_module, "urlpatterns", self.urlconf_module)
  File "/usr/local/lib/python2.7/site-packages/django/utils/functional.py", line 35, in __get__
    res = instance.__dict__[self.name] = self.func(instance)
  File "/usr/local/lib/python2.7/site-packages/django/urls/resolvers.py", line 400, in urlconf_module
    return import_module(self.urlconf_name)
  File "/usr/local/Cellar/python@2/2.7.15_1/Frameworks/Python.framework/Versions/2.7/lib/python2.7/importlib/__init__.py", line 37, in import_module
    __import__(name)
  File "/Users/pengbaojiang/pengbaojiang/code/python_src/python_learning/snower/pollsite/pollsite/pollsite/urls.py", line 21, in <module>
    url(r'^snower/', include('snower.urls')),
  File "/usr/local/lib/python2.7/site-packages/django/conf/urls/__init__.py", line 50, in include
    urlconf_module = import_module(urlconf_module)
  File "/usr/local/Cellar/python@2/2.7.15_1/Frameworks/Python.framework/Versions/2.7/lib/python2.7/importlib/__init__.py", line 37, in import_module
    __import__(name)
  File "/Users/pengbaojiang/pengbaojiang/code/python_src/python_learning/snower/pollsite/pollsite/snower/urls.py", line 8, in <module>
    url(r'^imagekitchen/data/$', views.imagedata)
AttributeError: 'module' object has no attribute 'imagedata'
Unhandled exception in thread started by <function wrapper at 0x1103b9500>
Performing system checks...

Traceback (most recent call last):
  File "/usr/local/lib/python2.7/site-packages/django/utils/autoreload.py", line 228, in wrapper
    fn(*args, **kwargs)
  File "/usr/local/lib/python2.7/site-packages/django/core/management/commands/runserver.py", line 124, in inner_run
    self.check(display_num_errors=True)
  File "/usr/local/lib/python2.7/site-packages/django/core/management/base.py", line 359, in check
    include_deployment_checks=include_deployment_checks,
  File "/usr/local/lib/python2.7/site-packages/django/core/management/base.py", line 346, in _run_checks
    return checks.run_checks(**kwargs)
  File "/usr/local/lib/python2.7/site-packages/django/core/checks/registry.py", line 81, in run_checks
    new_errors = check(app_configs=app_configs)
  File "/usr/local/lib/python2.7/site-packages/django/core/checks/urls.py", line 16, in check_url_config
    return check_resolver(resolver)
  File "/usr/local/lib/python2.7/site-packages/django/core/checks/urls.py", line 26, in check_resolver
    return check_method()
  File "/usr/local/lib/python2.7/site-packages/django/urls/resolvers.py", line 256, in check
    for pattern in self.url_patterns:
  File "/usr/local/lib/python2.7/site-packages/django/utils/functional.py", line 35, in __get__
    res = instance.__dict__[self.name] = self.func(instance)
  File "/usr/local/lib/python2.7/site-packages/django/urls/resolvers.py", line 407, in url_patterns
    patterns = getattr(self.urlconf_module, "urlpatterns", self.urlconf_module)
  File "/usr/local/lib/python2.7/site-packages/django/utils/functional.py", line 35, in __get__
    res = instance.__dict__[self.name] = self.func(instance)
  File "/usr/local/lib/python2.7/site-packages/django/urls/resolvers.py", line 400, in urlconf_module
    return import_module(self.urlconf_name)
  File "/usr/local/Cellar/python@2/2.7.15_1/Frameworks/Python.framework/Versions/2.7/lib/python2.7/importlib/__init__.py", line 37, in import_module
    __import__(name)
  File "/Users/pengbaojiang/pengbaojiang/code/python_src/python_learning/snower/pollsite/pollsite/pollsite/urls.py", line 21, in <module>
    url(r'^snower/', include('snower.urls')),
  File "/usr/local/lib/python2.7/site-packages/django/conf/urls/__init__.py", line 50, in include
    urlconf_module = import_module(urlconf_module)
  File "/usr/local/Cellar/python@2/2.7.15_1/Frameworks/Python.framework/Versions/2.7/lib/python2.7/importlib/__init__.py", line 37, in import_module
    __import__(name)
  File "/Users/pengbaojiang/pengbaojiang/code/python_src/python_learning/snower/pollsite/pollsite/snower/urls.py", line 8, in <module>
    url(r'^imagekitchen/data/$', views.imagedata, name="iamgedata")
AttributeError: 'module' object has no attribute 'imagedata'
Unhandled exception in thread started by <function wrapper at 0x10fcc4500>
Performing system checks...

Traceback (most recent call last):
  File "/usr/local/lib/python2.7/site-packages/django/utils/autoreload.py", line 228, in wrapper
    fn(*args, **kwargs)
  File "/usr/local/lib/python2.7/site-packages/django/core/management/commands/runserver.py", line 124, in inner_run
    self.check(display_num_errors=True)
  File "/usr/local/lib/python2.7/site-packages/django/core/management/base.py", line 359, in check
    include_deployment_checks=include_deployment_checks,
  File "/usr/local/lib/python2.7/site-packages/django/core/management/base.py", line 346, in _run_checks
    return checks.run_checks(**kwargs)
  File "/usr/local/lib/python2.7/site-packages/django/core/checks/registry.py", line 81, in run_checks
    new_errors = check(app_configs=app_configs)
  File "/usr/local/lib/python2.7/site-packages/django/core/checks/urls.py", line 16, in check_url_config
    return check_resolver(resolver)
  File "/usr/local/lib/python2.7/site-packages/django/core/checks/urls.py", line 26, in check_resolver
    return check_method()
  File "/usr/local/lib/python2.7/site-packages/django/urls/resolvers.py", line 256, in check
    for pattern in self.url_patterns:
  File "/usr/local/lib/python2.7/site-packages/django/utils/functional.py", line 35, in __get__
    res = instance.__dict__[self.name] = self.func(instance)
  File "/usr/local/lib/python2.7/site-packages/django/urls/resolvers.py", line 407, in url_patterns
    patterns = getattr(self.urlconf_module, "urlpatterns", self.urlconf_module)
  File "/usr/local/lib/python2.7/site-packages/django/utils/functional.py", line 35, in __get__
    res = instance.__dict__[self.name] = self.func(instance)
  File "/usr/local/lib/python2.7/site-packages/django/urls/resolvers.py", line 400, in urlconf_module
    return import_module(self.urlconf_name)
  File "/usr/local/Cellar/python@2/2.7.15_1/Frameworks/Python.framework/Versions/2.7/lib/python2.7/importlib/__init__.py", line 37, in import_module
    __import__(name)
  File "/Users/pengbaojiang/pengbaojiang/code/python_src/python_learning/snower/pollsite/pollsite/pollsite/urls.py", line 21, in <module>
    url(r'^snower/', include('snower.urls')),
  File "/usr/local/lib/python2.7/site-packages/django/conf/urls/__init__.py", line 50, in include
    urlconf_module = import_module(urlconf_module)
  File "/usr/local/Cellar/python@2/2.7.15_1/Frameworks/Python.framework/Versions/2.7/lib/python2.7/importlib/__init__.py", line 37, in import_module
    __import__(name)
  File "/Users/pengbaojiang/pengbaojiang/code/python_src/python_learning/snower/pollsite/pollsite/snower/urls.py", line 8, in <module>
    url(r'^imagekitchen/data/$', views.imagedata, name="iamgedata"),
AttributeError: 'module' object has no attribute 'imagedata'
Unhandled exception in thread started by <function wrapper at 0x107853500>
Performing system checks...

Traceback (most recent call last):
  File "/usr/local/lib/python2.7/site-packages/django/utils/autoreload.py", line 228, in wrapper
    fn(*args, **kwargs)
  File "/usr/local/lib/python2.7/site-packages/django/core/management/commands/runserver.py", line 124, in inner_run
    self.check(display_num_errors=True)
  File "/usr/local/lib/python2.7/site-packages/django/core/management/base.py", line 359, in check
    include_deployment_checks=include_deployment_checks,
  File "/usr/local/lib/python2.7/site-packages/django/core/management/base.py", line 346, in _run_checks
    return checks.run_checks(**kwargs)
  File "/usr/local/lib/python2.7/site-packages/django/core/checks/registry.py", line 81, in run_checks
    new_errors = check(app_configs=app_configs)
  File "/usr/local/lib/python2.7/site-packages/django/core/checks/urls.py", line 16, in check_url_config
    return check_resolver(resolver)
  File "/usr/local/lib/python2.7/site-packages/django/core/checks/urls.py", line 26, in check_resolver
    return check_method()
  File "/usr/local/lib/python2.7/site-packages/django/urls/resolvers.py", line 256, in check
    for pattern in self.url_patterns:
  File "/usr/local/lib/python2.7/site-packages/django/utils/functional.py", line 35, in __get__
    res = instance.__dict__[self.name] = self.func(instance)
  File "/usr/local/lib/python2.7/site-packages/django/urls/resolvers.py", line 407, in url_patterns
    patterns = getattr(self.urlconf_module, "urlpatterns", self.urlconf_module)
  File "/usr/local/lib/python2.7/site-packages/django/utils/functional.py", line 35, in __get__
    res = instance.__dict__[self.name] = self.func(instance)
  File "/usr/local/lib/python2.7/site-packages/django/urls/resolvers.py", line 400, in urlconf_module
    return import_module(self.urlconf_name)
  File "/usr/local/Cellar/python@2/2.7.15_1/Frameworks/Python.framework/Versions/2.7/lib/python2.7/importlib/__init__.py", line 37, in import_module
    __import__(name)
  File "/Users/pengbaojiang/pengbaojiang/code/python_src/python_learning/snower/pollsite/pollsite/pollsite/urls.py", line 21, in <module>
    url(r'^snower/', include('snower.urls')),
  File "/usr/local/lib/python2.7/site-packages/django/conf/urls/__init__.py", line 50, in include
    urlconf_module = import_module(urlconf_module)
  File "/usr/local/Cellar/python@2/2.7.15_1/Frameworks/Python.framework/Versions/2.7/lib/python2.7/importlib/__init__.py", line 37, in import_module
    __import__(name)
  File "/Users/pengbaojiang/pengbaojiang/code/python_src/python_learning/snower/pollsite/pollsite/snower/urls.py", line 3, in <module>
    from . import views
  File "/Users/pengbaojiang/pengbaojiang/code/python_src/python_learning/snower/pollsite/pollsite/snower/views.py", line 22
    
    ^
IndentationError: expected an indented block
Performing system checks...

System check identified no issues (0 silenced).
September 14, 2018 - 15:03:40
Django version 1.11.15, using settings 'pollsite.settings'
Starting development server at http://127.0.0.1:8000/
Quit the server with CONTROL-C.
Performing system checks...

System check identified no issues (0 silenced).
September 14, 2018 - 15:11:30
Django version 1.11.15, using settings 'pollsite.settings'
Starting development server at http://127.0.0.1:8000/
Quit the server with CONTROL-C.
Performing system checks...

System check identified no issues (0 silenced).
September 14, 2018 - 15:11:35
Django version 1.11.15, using settings 'pollsite.settings'
Starting development server at http://127.0.0.1:8000/
Quit the server with CONTROL-C.
[14/Sep/2018 15:13:09] "GET /snower/imagekitchen/ HTTP/1.1" 200 13
[14/Sep/2018 15:13:10] "GET /snower/imagekitchen/ HTTP/1.1" 200 13
[14/Sep/2018 15:13:17] "GET /snower/imagekitchen/ HTTP/1.1" 200 13
Performing system checks...

System check identified no issues (0 silenced).
September 14, 2018 - 15:11:38
Django version 1.11.15, using settings 'pollsite.settings'
Starting development server at http://127.0.0.1:8000/
Quit the server with CONTROL-C.
Internal Server Error: /snower/imagekitchen/
Traceback (most recent call last):
  File "/usr/local/lib/python2.7/site-packages/django/core/handlers/exception.py", line 41, in inner
    response = get_response(request)
  File "/usr/local/lib/python2.7/site-packages/django/core/handlers/base.py", line 187, in _get_response
    response = self.process_exception_by_middleware(e, request)
  File "/usr/local/lib/python2.7/site-packages/django/core/handlers/base.py", line 185, in _get_response
    response = wrapped_callback(request, *callback_args, **callback_kwargs)
  File "/Users/pengbaojiang/pengbaojiang/code/python_src/python_learning/snower/pollsite/pollsite/snower/views.py", line 17, in imagekitchen
    return render(request, 'snower/imagekitchen.html')
  File "/usr/local/lib/python2.7/site-packages/django/shortcuts.py", line 30, in render
    content = loader.render_to_string(template_name, context, request, using=using)
  File "/usr/local/lib/python2.7/site-packages/django/template/loader.py", line 68, in render_to_string
    return template.render(context, request)
  File "/usr/local/lib/python2.7/site-packages/django/template/backends/django.py", line 66, in render
    return self.template.render(context)
  File "/usr/local/lib/python2.7/site-packages/django/template/base.py", line 207, in render
    return self._render(context)
  File "/usr/local/lib/python2.7/site-packages/django/template/base.py", line 199, in _render
    return self.nodelist.render(context)
  File "/usr/local/lib/python2.7/site-packages/django/template/base.py", line 990, in render
    bit = node.render_annotated(context)
  File "/usr/local/lib/python2.7/site-packages/django/template/base.py", line 957, in render_annotated
    return self.render(context)
  File "/usr/local/lib/python2.7/site-packages/django/template/defaulttags.py", line 458, in render
    url = reverse(view_name, args=args, kwargs=kwargs, current_app=current_app)
  File "/usr/local/lib/python2.7/site-packages/django/urls/base.py", line 91, in reverse
    return force_text(iri_to_uri(resolver._reverse_with_prefix(view, prefix, *args, **kwargs)))
  File "/usr/local/lib/python2.7/site-packages/django/urls/resolvers.py", line 497, in _reverse_with_prefix
    raise NoReverseMatch(msg)
NoReverseMatch: Reverse for '' not found. '' is not a valid view function or pattern name.
[14/Sep/2018 15:14:06] "GET /snower/imagekitchen/ HTTP/1.1" 500 109772
Internal Server Error: /snower/imagekitchen/
Traceback (most recent call last):
  File "/usr/local/lib/python2.7/site-packages/django/core/handlers/exception.py", line 41, in inner
    response = get_response(request)
  File "/usr/local/lib/python2.7/site-packages/django/core/handlers/base.py", line 187, in _get_response
    response = self.process_exception_by_middleware(e, request)
  File "/usr/local/lib/python2.7/site-packages/django/core/handlers/base.py", line 185, in _get_response
    response = wrapped_callback(request, *callback_args, **callback_kwargs)
  File "/Users/pengbaojiang/pengbaojiang/code/python_src/python_learning/snower/pollsite/pollsite/snower/views.py", line 17, in imagekitchen
    return render(request, 'snower/imagekitchen.html')
  File "/usr/local/lib/python2.7/site-packages/django/shortcuts.py", line 30, in render
    content = loader.render_to_string(template_name, context, request, using=using)
  File "/usr/local/lib/python2.7/site-packages/django/template/loader.py", line 68, in render_to_string
    return template.render(context, request)
  File "/usr/local/lib/python2.7/site-packages/django/template/backends/django.py", line 66, in render
    return self.template.render(context)
  File "/usr/local/lib/python2.7/site-packages/django/template/base.py", line 207, in render
    return self._render(context)
  File "/usr/local/lib/python2.7/site-packages/django/template/base.py", line 199, in _render
    return self.nodelist.render(context)
  File "/usr/local/lib/python2.7/site-packages/django/template/base.py", line 990, in render
    bit = node.render_annotated(context)
  File "/usr/local/lib/python2.7/site-packages/django/template/base.py", line 957, in render_annotated
    return self.render(context)
  File "/usr/local/lib/python2.7/site-packages/django/template/defaulttags.py", line 458, in render
    url = reverse(view_name, args=args, kwargs=kwargs, current_app=current_app)
  File "/usr/local/lib/python2.7/site-packages/django/urls/base.py", line 91, in reverse
    return force_text(iri_to_uri(resolver._reverse_with_prefix(view, prefix, *args, **kwargs)))
  File "/usr/local/lib/python2.7/site-packages/django/urls/resolvers.py", line 497, in _reverse_with_prefix
    raise NoReverseMatch(msg)
NoReverseMatch: Reverse for 'imagedata' not found. 'imagedata' is not a valid view function or pattern name.
[14/Sep/2018 15:15:10] "GET /snower/imagekitchen/ HTTP/1.1" 500 110028
Internal Server Error: /snower/imagekitchen/
Traceback (most recent call last):
  File "/usr/local/lib/python2.7/site-packages/django/core/handlers/exception.py", line 41, in inner
    response = get_response(request)
  File "/usr/local/lib/python2.7/site-packages/django/core/handlers/base.py", line 187, in _get_response
    response = self.process_exception_by_middleware(e, request)
  File "/usr/local/lib/python2.7/site-packages/django/core/handlers/base.py", line 185, in _get_response
    response = wrapped_callback(request, *callback_args, **callback_kwargs)
  File "/Users/pengbaojiang/pengbaojiang/code/python_src/python_learning/snower/pollsite/pollsite/snower/views.py", line 17, in imagekitchen
    return render(request, 'snower/imagekitchen.html')
  File "/usr/local/lib/python2.7/site-packages/django/shortcuts.py", line 30, in render
    content = loader.render_to_string(template_name, context, request, using=using)
  File "/usr/local/lib/python2.7/site-packages/django/template/loader.py", line 68, in render_to_string
    return template.render(context, request)
  File "/usr/local/lib/python2.7/site-packages/django/template/backends/django.py", line 66, in render
    return self.template.render(context)
  File "/usr/local/lib/python2.7/site-packages/django/template/base.py", line 207, in render
    return self._render(context)
  File "/usr/local/lib/python2.7/site-packages/django/template/base.py", line 199, in _render
    return self.nodelist.render(context)
  File "/usr/local/lib/python2.7/site-packages/django/template/base.py", line 990, in render
    bit = node.render_annotated(context)
  File "/usr/local/lib/python2.7/site-packages/django/template/base.py", line 957, in render_annotated
    return self.render(context)
  File "/usr/local/lib/python2.7/site-packages/django/template/defaulttags.py", line 458, in render
    url = reverse(view_name, args=args, kwargs=kwargs, current_app=current_app)
  File "/usr/local/lib/python2.7/site-packages/django/urls/base.py", line 91, in reverse
    return force_text(iri_to_uri(resolver._reverse_with_prefix(view, prefix, *args, **kwargs)))
  File "/usr/local/lib/python2.7/site-packages/django/urls/resolvers.py", line 497, in _reverse_with_prefix
    raise NoReverseMatch(msg)
NoReverseMatch: Reverse for 'imagedata' not found. 'imagedata' is not a valid view function or pattern name.
[14/Sep/2018 15:15:12] "GET /snower/imagekitchen/ HTTP/1.1" 500 110028
Performing system checks...

System check identified no issues (0 silenced).
September 14, 2018 - 15:14:06
Django version 1.11.15, using settings 'pollsite.settings'
Starting development server at http://127.0.0.1:8000/
Quit the server with CONTROL-C.
[14/Sep/2018 15:15:33] "GET /snower/imagekitchen/ HTTP/1.1" 200 95
[14/Sep/2018 15:15:35] "GET /snower/imagekitchen/data/ HTTP/1.1" 200 55
[14/Sep/2018 15:15:40] "GET /snower/imagekitchen/data/ HTTP/1.1" 200 55
Performing system checks...

System check identified no issues (0 silenced).
September 14, 2018 - 15:15:33
Django version 1.11.15, using settings 'pollsite.settings'
Starting development server at http://127.0.0.1:8000/
Quit the server with CONTROL-C.
Performing system checks...

System check identified no issues (0 silenced).
September 14, 2018 - 15:16:39
Django version 1.11.15, using settings 'pollsite.settings'
Starting development server at http://127.0.0.1:8000/
Quit the server with CONTROL-C.
Performing system checks...

System check identified no issues (0 silenced).
September 14, 2018 - 15:16:44
Django version 1.11.15, using settings 'pollsite.settings'
Starting development server at http://127.0.0.1:8000/
Quit the server with CONTROL-C.
[14/Sep/2018 15:16:48] "GET /snower/imagekitchen/data/ HTTP/1.1" 200 55
Performing system checks...

System check identified no issues (0 silenced).
September 14, 2018 - 15:16:48
Django version 1.11.15, using settings 'pollsite.settings'
Starting development server at http://127.0.0.1:8000/
Quit the server with CONTROL-C.
{}
[14/Sep/2018 15:18:07] "GET /snower/imagekitchen/data/ HTTP/1.1" 200 55
[14/Sep/2018 15:19:20] "GET /snower/imagekitchen/data/ HTTP/1.1" 200 55
[14/Sep/2018 15:20:10] "GET /snower/imagekitchen/data/ HTTP/1.1" 200 55
[14/Sep/2018 15:20:12] "GET /snower/imagekitchen/data/ HTTP/1.1" 200 55
Performing system checks...

System check identified no issues (0 silenced).
September 14, 2018 - 15:18:05
Django version 1.11.15, using settings 'pollsite.settings'
Starting development server at http://127.0.0.1:8000/
Quit the server with CONTROL-C.
{'db_key': 'pcloud:allimages:snow', 'dir_path': '/Users/pengbaojiang/pengbaojiang/code/python_src/python_learning/data/map_img/', 'img_num': '4224'}
{'db_key': 'pcloud:allimages:snow', 'dir_path': '/Users/pengbaojiang/pengbaojiang/code/python_src/python_learning/data/map_img/', 'img_num': '4224'}
{'db_key': 'pcloud:allimages:snow', 'dir_path': '/Users/pengbaojiang/pengbaojiang/code/python_src/python_learning/data/map_img/', 'img_num': '4224'}
{'db_key': 'pcloud:allimages:snow', 'dir_path': '/Users/pengbaojiang/pengbaojiang/code/python_src/python_learning/data/map_img/', 'img_num': '4224'}
Performing system checks...

System check identified no issues (0 silenced).
September 14, 2018 - 15:22:01
Django version 1.11.15, using settings 'pollsite.settings'
Starting development server at http://127.0.0.1:8000/
Quit the server with CONTROL-C.
[14/Sep/2018 15:22:24] "GET /snower/imagekitchen/data/ HTTP/1.1" 200 130
[14/Sep/2018 15:22:47] "GET /snower/imagekitchen/data/ HTTP/1.1" 200 236
[14/Sep/2018 15:23:00] "GET /snower/imagekitchen/data/ HTTP/1.1" 200 239
[14/Sep/2018 15:23:38] "GET /snower/imagekitchen/data/ HTTP/1.1" 200 239
[14/Sep/2018 15:23:40] "GET /snower/imagekitchen/data/ HTTP/1.1" 200 239
[14/Sep/2018 15:23:53] "GET /snower/imagekitchen/data/ HTTP/1.1" 200 239
[14/Sep/2018 15:23:55] "GET /snower/imagekitchen/data/ HTTP/1.1" 200 239
[14/Sep/2018 15:23:57] "GET /snower/imagekitchen/data/ HTTP/1.1" 200 239
Performing system checks...

System check identified no issues (0 silenced).
September 14, 2018 - 15:22:20
Django version 1.11.15, using settings 'pollsite.settings'
Starting development server at http://127.0.0.1:8000/
Quit the server with CONTROL-C.
{'db_key': 'pcloud:allimages:snow', 'dir_path': '/Users/pengbaojiang/pengbaojiang/code/python_src/python_learning/data/map_img/', 'img_num': '4224'}
{'db_key': 'pcloud:allimages:snow', 'dir_path': '/Users/pengbaojiang/pengbaojiang/code/python_src/python_learning/data/map_img/', 'img_num': '4224'}
{'db_key': 'pcloud:allimages:snow', 'dir_path': '/Users/pengbaojiang/pengbaojiang/code/python_src/python_learning/data/map_img/', 'img_num': '4224'}
{'db_key': 'pcloud:allimages:snow', 'dir_path': '/Users/pengbaojiang/pengbaojiang/code/python_src/python_learning/data/map_img/', 'img_num': '4224'}
{'db_key': 'pcloud:allimages:snow', 'dir_path': '/Users/pengbaojiang/pengbaojiang/code/python_src/python_learning/data/map_img/', 'img_num': '4224'}
{'db_key': 'pcloud:allimages:snow', 'dir_path': '/Users/pengbaojiang/pengbaojiang/code/python_src/python_learning/data/map_img/', 'img_num': '4224'}
{'db_key': 'pcloud:allimages:snow', 'dir_path': '/Users/pengbaojiang/pengbaojiang/code/python_src/python_learning/data/map_img/', 'img_num': '4224'}
{'db_key': 'pcloud:allimages:snow', 'dir_path': '/Users/pengbaojiang/pengbaojiang/code/python_src/python_learning/data/map_img/', 'img_num': '4224'}
Performing system checks...

System check identified no issues (0 silenced).
September 14, 2018 - 15:26:29
Django version 1.11.15, using settings 'pollsite.settings'
Starting development server at http://127.0.0.1:8000/
Quit the server with CONTROL-C.
Performing system checks...

System check identified no issues (0 silenced).
September 14, 2018 - 15:27:15
Django version 1.11.15, using settings 'pollsite.settings'
Starting development server at http://127.0.0.1:8000/
Quit the server with CONTROL-C.
Performing system checks...

System check identified no issues (0 silenced).
September 14, 2018 - 15:27:23
Django version 1.11.15, using settings 'pollsite.settings'
Starting development server at http://127.0.0.1:8000/
Quit the server with CONTROL-C.
Performing system checks...

System check identified no issues (0 silenced).
September 14, 2018 - 15:27:26
Django version 1.11.15, using settings 'pollsite.settings'
Starting development server at http://127.0.0.1:8000/
Quit the server with CONTROL-C.
[14/Sep/2018 15:27:40] "GET /snower/imagekitchen/data/ HTTP/1.1" 200 239
Performing system checks...

System check identified no issues (0 silenced).
September 14, 2018 - 15:27:29
Django version 1.11.15, using settings 'pollsite.settings'
Starting development server at http://127.0.0.1:8000/
Quit the server with CONTROL-C.
Unhandled exception in thread started by <function wrapper at 0x10b6ed500>
Performing system checks...

Traceback (most recent call last):
  File "/usr/local/lib/python2.7/site-packages/django/utils/autoreload.py", line 228, in wrapper
    fn(*args, **kwargs)
  File "/usr/local/lib/python2.7/site-packages/django/core/management/commands/runserver.py", line 124, in inner_run
    self.check(display_num_errors=True)
  File "/usr/local/lib/python2.7/site-packages/django/core/management/base.py", line 359, in check
    include_deployment_checks=include_deployment_checks,
  File "/usr/local/lib/python2.7/site-packages/django/core/management/base.py", line 346, in _run_checks
    return checks.run_checks(**kwargs)
  File "/usr/local/lib/python2.7/site-packages/django/core/checks/registry.py", line 81, in run_checks
    new_errors = check(app_configs=app_configs)
  File "/usr/local/lib/python2.7/site-packages/django/core/checks/urls.py", line 16, in check_url_config
    return check_resolver(resolver)
  File "/usr/local/lib/python2.7/site-packages/django/core/checks/urls.py", line 26, in check_resolver
    return check_method()
  File "/usr/local/lib/python2.7/site-packages/django/urls/resolvers.py", line 256, in check
    for pattern in self.url_patterns:
  File "/usr/local/lib/python2.7/site-packages/django/utils/functional.py", line 35, in __get__
    res = instance.__dict__[self.name] = self.func(instance)
  File "/usr/local/lib/python2.7/site-packages/django/urls/resolvers.py", line 407, in url_patterns
    patterns = getattr(self.urlconf_module, "urlpatterns", self.urlconf_module)
  File "/usr/local/lib/python2.7/site-packages/django/utils/functional.py", line 35, in __get__
    res = instance.__dict__[self.name] = self.func(instance)
  File "/usr/local/lib/python2.7/site-packages/django/urls/resolvers.py", line 400, in urlconf_module
    return import_module(self.urlconf_name)
  File "/usr/local/Cellar/python@2/2.7.15_1/Frameworks/Python.framework/Versions/2.7/lib/python2.7/importlib/__init__.py", line 37, in import_module
    __import__(name)
  File "/Users/pengbaojiang/pengbaojiang/code/python_src/python_learning/snower/pollsite/pollsite/pollsite/urls.py", line 21, in <module>
    url(r'^snower/', include('snower.urls')),
  File "/usr/local/lib/python2.7/site-packages/django/conf/urls/__init__.py", line 50, in include
    urlconf_module = import_module(urlconf_module)
  File "/usr/local/Cellar/python@2/2.7.15_1/Frameworks/Python.framework/Versions/2.7/lib/python2.7/importlib/__init__.py", line 37, in import_module
    __import__(name)
  File "/Users/pengbaojiang/pengbaojiang/code/python_src/python_learning/snower/pollsite/pollsite/snower/urls.py", line 9, in <module>
    url(r'^imagekitchen/allimage/$', views.allimages, name="allimages")
AttributeError: 'module' object has no attribute 'allimages'
Performing system checks...

System check identified no issues (0 silenced).
September 14, 2018 - 15:32:39
Django version 1.11.15, using settings 'pollsite.settings'
Starting development server at http://127.0.0.1:8000/
Quit the server with CONTROL-C.
[14/Sep/2018 15:33:38] "GET /snower/imagekitchen/ HTTP/1.1" 200 155
Internal Server Error: /snower/imagekitchen/allimage/
Traceback (most recent call last):
  File "/usr/local/lib/python2.7/site-packages/django/core/handlers/exception.py", line 41, in inner
    response = get_response(request)
  File "/usr/local/lib/python2.7/site-packages/django/core/handlers/base.py", line 187, in _get_response
    response = self.process_exception_by_middleware(e, request)
  File "/usr/local/lib/python2.7/site-packages/django/core/handlers/base.py", line 185, in _get_response
    response = wrapped_callback(request, *callback_args, **callback_kwargs)
  File "/Users/pengbaojiang/pengbaojiang/code/python_src/python_learning/snower/pollsite/pollsite/snower/views.py", line 26, in allimages
    all_images = redisc.allimages()
AttributeError: 'module' object has no attribute 'allimages'
[14/Sep/2018 15:33:40] "GET /snower/imagekitchen/allimage/ HTTP/1.1" 500 63514
[14/Sep/2018 15:33:57] "GET /snower/imagekitchen/ HTTP/1.1" 200 166
Internal Server Error: /snower/imagekitchen/allimage/
Traceback (most recent call last):
  File "/usr/local/lib/python2.7/site-packages/django/core/handlers/exception.py", line 41, in inner
    response = get_response(request)
  File "/usr/local/lib/python2.7/site-packages/django/core/handlers/base.py", line 187, in _get_response
    response = self.process_exception_by_middleware(e, request)
  File "/usr/local/lib/python2.7/site-packages/django/core/handlers/base.py", line 185, in _get_response
    response = wrapped_callback(request, *callback_args, **callback_kwargs)
  File "/Users/pengbaojiang/pengbaojiang/code/python_src/python_learning/snower/pollsite/pollsite/snower/views.py", line 26, in allimages
    all_images = redisc.allimages()
AttributeError: 'module' object has no attribute 'allimages'
[14/Sep/2018 15:34:04] "GET /snower/imagekitchen/allimage/ HTTP/1.1" 500 63514
Performing system checks...

System check identified no issues (0 silenced).
September 14, 2018 - 15:32:53
Django version 1.11.15, using settings 'pollsite.settings'
Starting development server at http://127.0.0.1:8000/
Quit the server with CONTROL-C.
Internal Server Error: /snower/imagekitchen/allimage/
Traceback (most recent call last):
  File "/usr/local/lib/python2.7/site-packages/django/core/handlers/exception.py", line 41, in inner
    response = get_response(request)
  File "/usr/local/lib/python2.7/site-packages/django/core/handlers/base.py", line 187, in _get_response
    response = self.process_exception_by_middleware(e, request)
  File "/usr/local/lib/python2.7/site-packages/django/core/handlers/base.py", line 185, in _get_response
    response = wrapped_callback(request, *callback_args, **callback_kwargs)
  File "/Users/pengbaojiang/pengbaojiang/code/python_src/python_learning/snower/pollsite/pollsite/snower/views.py", line 29, in allimages
    return render(request, 'snower/list.html', params)
  File "/usr/local/lib/python2.7/site-packages/django/shortcuts.py", line 30, in render
    content = loader.render_to_string(template_name, context, request, using=using)
  File "/usr/local/lib/python2.7/site-packages/django/template/loader.py", line 67, in render_to_string
    template = get_template(template_name, using=using)
  File "/usr/local/lib/python2.7/site-packages/django/template/loader.py", line 21, in get_template
    return engine.get_template(template_name)
  File "/usr/local/lib/python2.7/site-packages/django/template/backends/django.py", line 39, in get_template
    return Template(self.engine.get_template(template_name), self)
  File "/usr/local/lib/python2.7/site-packages/django/template/engine.py", line 162, in get_template
    template, origin = self.find_template(template_name)
  File "/usr/local/lib/python2.7/site-packages/django/template/engine.py", line 136, in find_template
    name, template_dirs=dirs, skip=skip,
  File "/usr/local/lib/python2.7/site-packages/django/template/loaders/base.py", line 44, in get_template
    contents, origin, origin.template_name, self.engine,
  File "/usr/local/lib/python2.7/site-packages/django/template/base.py", line 191, in __init__
    self.nodelist = self.compile_nodelist()
  File "/usr/local/lib/python2.7/site-packages/django/template/base.py", line 230, in compile_nodelist
    return parser.parse()
  File "/usr/local/lib/python2.7/site-packages/django/template/base.py", line 515, in parse
    raise self.error(token, e)
TemplateSyntaxError: Unclosed tag on line 3: 'for'. Looking for one of: empty, endfor.
[14/Sep/2018 15:34:51] "GET /snower/imagekitchen/allimage/ HTTP/1.1" 500 126626
Internal Server Error: /snower/imagekitchen/allimage/
Traceback (most recent call last):
  File "/usr/local/lib/python2.7/site-packages/django/core/handlers/exception.py", line 41, in inner
    response = get_response(request)
  File "/usr/local/lib/python2.7/site-packages/django/core/handlers/base.py", line 187, in _get_response
    response = self.process_exception_by_middleware(e, request)
  File "/usr/local/lib/python2.7/site-packages/django/core/handlers/base.py", line 185, in _get_response
    response = wrapped_callback(request, *callback_args, **callback_kwargs)
  File "/Users/pengbaojiang/pengbaojiang/code/python_src/python_learning/snower/pollsite/pollsite/snower/views.py", line 29, in allimages
    return render(request, 'snower/list.html', params)
  File "/usr/local/lib/python2.7/site-packages/django/shortcuts.py", line 30, in render
    content = loader.render_to_string(template_name, context, request, using=using)
  File "/usr/local/lib/python2.7/site-packages/django/template/loader.py", line 67, in render_to_string
    template = get_template(template_name, using=using)
  File "/usr/local/lib/python2.7/site-packages/django/template/loader.py", line 21, in get_template
    return engine.get_template(template_name)
  File "/usr/local/lib/python2.7/site-packages/django/template/backends/django.py", line 39, in get_template
    return Template(self.engine.get_template(template_name), self)
  File "/usr/local/lib/python2.7/site-packages/django/template/engine.py", line 162, in get_template
    template, origin = self.find_template(template_name)
  File "/usr/local/lib/python2.7/site-packages/django/template/engine.py", line 136, in find_template
    name, template_dirs=dirs, skip=skip,
  File "/usr/local/lib/python2.7/site-packages/django/template/loaders/base.py", line 44, in get_template
    contents, origin, origin.template_name, self.engine,
  File "/usr/local/lib/python2.7/site-packages/django/template/base.py", line 191, in __init__
    self.nodelist = self.compile_nodelist()
  File "/usr/local/lib/python2.7/site-packages/django/template/base.py", line 230, in compile_nodelist
    return parser.parse()
  File "/usr/local/lib/python2.7/site-packages/django/template/base.py", line 515, in parse
    raise self.error(token, e)
TemplateSyntaxError: Unclosed tag on line 3: 'for'. Looking for one of: empty, endfor.
[14/Sep/2018 15:35:16] "GET /snower/imagekitchen/allimage/ HTTP/1.1" 500 126626
Internal Server Error: /snower/imagekitchen/allimage/
Traceback (most recent call last):
  File "/usr/local/lib/python2.7/site-packages/django/core/handlers/exception.py", line 41, in inner
    response = get_response(request)
  File "/usr/local/lib/python2.7/site-packages/django/core/handlers/base.py", line 187, in _get_response
    response = self.process_exception_by_middleware(e, request)
  File "/usr/local/lib/python2.7/site-packages/django/core/handlers/base.py", line 185, in _get_response
    response = wrapped_callback(request, *callback_args, **callback_kwargs)
  File "/Users/pengbaojiang/pengbaojiang/code/python_src/python_learning/snower/pollsite/pollsite/snower/views.py", line 29, in allimages
    return render(request, 'snower/list.html', params)
  File "/usr/local/lib/python2.7/site-packages/django/shortcuts.py", line 30, in render
    content = loader.render_to_string(template_name, context, request, using=using)
  File "/usr/local/lib/python2.7/site-packages/django/template/loader.py", line 67, in render_to_string
    template = get_template(template_name, using=using)
  File "/usr/local/lib/python2.7/site-packages/django/template/loader.py", line 21, in get_template
    return engine.get_template(template_name)
  File "/usr/local/lib/python2.7/site-packages/django/template/backends/django.py", line 39, in get_template
    return Template(self.engine.get_template(template_name), self)
  File "/usr/local/lib/python2.7/site-packages/django/template/engine.py", line 162, in get_template
    template, origin = self.find_template(template_name)
  File "/usr/local/lib/python2.7/site-packages/django/template/engine.py", line 136, in find_template
    name, template_dirs=dirs, skip=skip,
  File "/usr/local/lib/python2.7/site-packages/django/template/loaders/base.py", line 44, in get_template
    contents, origin, origin.template_name, self.engine,
  File "/usr/local/lib/python2.7/site-packages/django/template/base.py", line 191, in __init__
    self.nodelist = self.compile_nodelist()
  File "/usr/local/lib/python2.7/site-packages/django/template/base.py", line 230, in compile_nodelist
    return parser.parse()
  File "/usr/local/lib/python2.7/site-packages/django/template/base.py", line 515, in parse
    raise self.error(token, e)
TemplateSyntaxError: Unclosed tag on line 3: 'for'. Looking for one of: empty, endfor.
[14/Sep/2018 15:35:33] "GET /snower/imagekitchen/allimage/ HTTP/1.1" 500 126626
Internal Server Error: /snower/imagekitchen/allimage/
Traceback (most recent call last):
  File "/usr/local/lib/python2.7/site-packages/django/core/handlers/exception.py", line 41, in inner
    response = get_response(request)
  File "/usr/local/lib/python2.7/site-packages/django/core/handlers/base.py", line 187, in _get_response
    response = self.process_exception_by_middleware(e, request)
  File "/usr/local/lib/python2.7/site-packages/django/core/handlers/base.py", line 185, in _get_response
    response = wrapped_callback(request, *callback_args, **callback_kwargs)
  File "/Users/pengbaojiang/pengbaojiang/code/python_src/python_learning/snower/pollsite/pollsite/snower/views.py", line 29, in allimages
    return render(request, 'snower/list.html', params)
  File "/usr/local/lib/python2.7/site-packages/django/shortcuts.py", line 30, in render
    content = loader.render_to_string(template_name, context, request, using=using)
  File "/usr/local/lib/python2.7/site-packages/django/template/loader.py", line 67, in render_to_string
    template = get_template(template_name, using=using)
  File "/usr/local/lib/python2.7/site-packages/django/template/loader.py", line 21, in get_template
    return engine.get_template(template_name)
  File "/usr/local/lib/python2.7/site-packages/django/template/backends/django.py", line 39, in get_template
    return Template(self.engine.get_template(template_name), self)
  File "/usr/local/lib/python2.7/site-packages/django/template/engine.py", line 162, in get_template
    template, origin = self.find_template(template_name)
  File "/usr/local/lib/python2.7/site-packages/django/template/engine.py", line 136, in find_template
    name, template_dirs=dirs, skip=skip,
  File "/usr/local/lib/python2.7/site-packages/django/template/loaders/base.py", line 44, in get_template
    contents, origin, origin.template_name, self.engine,
  File "/usr/local/lib/python2.7/site-packages/django/template/base.py", line 191, in __init__
    self.nodelist = self.compile_nodelist()
  File "/usr/local/lib/python2.7/site-packages/django/template/base.py", line 230, in compile_nodelist
    return parser.parse()
  File "/usr/local/lib/python2.7/site-packages/django/template/base.py", line 515, in parse
    raise self.error(token, e)
TemplateSyntaxError: Unclosed tag on line 3: 'for'. Looking for one of: empty, endfor.
[14/Sep/2018 15:35:38] "GET /snower/imagekitchen/allimage/ HTTP/1.1" 500 126491
[14/Sep/2018 15:39:07] "GET /snower/imagekitchen/allimage/ HTTP/1.1" 200 505828
[14/Sep/2018 15:39:47] "GET /snower/imagekitchen/allimage/ HTTP/1.1" 200 867985
Not Found: /Users/pengbaojiang/pengbaojiang/code/python_src/python_learning/data/map_img/2567.png
[14/Sep/2018 15:39:49] "GET /Users/pengbaojiang/pengbaojiang/code/python_src/python_learning/data/map_img/2567.png HTTP/1.1" 404 2401
Not Found: /Users/pengbaojiang/pengbaojiang/code/python_src/python_learning/data/map_img/1320.png
[14/Sep/2018 15:40:13] "GET /Users/pengbaojiang/pengbaojiang/code/python_src/python_learning/data/map_img/1320.png HTTP/1.1" 404 2401
[14/Sep/2018 15:40:34] "GET /snower/imagekitchen/data/ HTTP/1.1" 200 239
[14/Sep/2018 15:40:47] "GET /snower/imagekitchen/ HTTP/1.1" 200 166
[14/Sep/2018 15:41:13] "GET /snower/imagekitchen/ HTTP/1.1" 200 166
[14/Sep/2018 15:41:35] "GET /snower/imagekitchen/data/ HTTP/1.1" 200 239
[14/Sep/2018 15:41:43] "GET /snower/imagekitchen/allimage/ HTTP/1.1" 200 867985
Not Found: /Users/pengbaojiang/pengbaojiang/code/python_src/python_learning/data/map_img/881.png
[14/Sep/2018 15:41:53] "GET /Users/pengbaojiang/pengbaojiang/code/python_src/python_learning/data/map_img/881.png HTTP/1.1" 404 2398
[14/Sep/2018 15:46:50] "GET /snower/imagekitchen/allimage/ HTTP/1.1" 200 901777
[14/Sep/2018 15:47:18] "GET /snower/imagekitchen/allimage/ HTTP/1.1" 200 897553
[14/Sep/2018 15:48:43] "GET /snower/imagekitchen/allimage/ HTTP/1.1" 200 867985
Not Found: /Users/pengbaojiang/pengbaojiang/code/python_src/python_learning/data/map_img/665.png
[14/Sep/2018 15:48:45] "GET /Users/pengbaojiang/pengbaojiang/code/python_src/python_learning/data/map_img/665.png HTTP/1.1" 404 2398
Not Found: /Users/pengbaojiang/pengbaojiang/code/python_src/python_learning/data/map_img/2608.png
[14/Sep/2018 15:50:19] "GET /Users/pengbaojiang/pengbaojiang/code/python_src/python_learning/data/map_img/2608.png HTTP/1.1" 404 2401
[14/Sep/2018 15:52:19] "GET /snower/imagekitchen/allimage/ HTTP/1.1" 200 893329
[14/Sep/2018 15:52:59] "GET /snower/imagekitchen/allimage/ HTTP/1.1" 200 889105
[14/Sep/2018 15:56:41] "GET /snower/imagekitchen/allimage/ HTTP/1.1" 200 889105
[14/Sep/2018 15:57:04] "GET /snower/imagekitchen/allimage/ HTTP/1.1" 200 889105
[14/Sep/2018 15:58:43] "GET /snower/imagekitchen/data/ HTTP/1.1" 200 239
[14/Sep/2018 15:58:51] "GET /snower/imagekitchen/allimage/ HTTP/1.1" 200 889105
[14/Sep/2018 15:59:05] "GET /snower/imagekitchen/ HTTP/1.1" 200 166
[14/Sep/2018 15:59:06] "GET /snower/imagekitchen/data/ HTTP/1.1" 200 239
[14/Sep/2018 15:59:09] "GET /snower/imagekitchen/allimage/ HTTP/1.1" 200 889105
[14/Sep/2018 15:59:30] "GET /snower/imagekitchen/allimage/ HTTP/1.1" 200 889105
[14/Sep/2018 16:43:07] "GET /snower/imagekitchen/allimage/ HTTP/1.1" 200 889105
Performing system checks...

System check identified no issues (0 silenced).
September 14, 2018 - 15:34:48
Django version 1.11.15, using settings 'pollsite.settings'
Starting development server at http://127.0.0.1:8000/
Quit the server with CONTROL-C.
Performing system checks...

System check identified no issues (0 silenced).
September 16, 2018 - 16:53:38
Django version 1.11.15, using settings 'pollsite.settings'
Starting development server at http://127.0.0.1:8000/
Quit the server with CONTROL-C.
Performing system checks...

System check identified no issues (0 silenced).
September 16, 2018 - 16:53:40
Django version 1.11.15, using settings 'pollsite.settings'
Starting development server at http://127.0.0.1:8000/
Quit the server with CONTROL-C.
